Workbook

Sheet README
A1: SCRUTINISE — CORPUS REGISTER v4
A2: Rebuilt 23 August 2026. Supersedes Legislation_Corpus_Breakdown_v3.xlsx.
A4: WHAT THIS WORKBOOK IS
A5: Every source the Scrutinise corpus holds, should hold, or has decided not to hold — in one list, with an honest completeness figure beside each one.
A7: THE ONE THING TO UNDERSTAND FIRST
A8: The daily ingest email has been reporting 62 of 77 collections as '100% complete'. For 46 of them the target was set by copying the number of sections we ended up with, and then marking it confirmed. The email was dividing a number by itself. 100% of nothing is still 100%.
A9: The tell was on the face of the email: explanatory-notes held 18,651 sections against a target of 410 — 4,549% of target — and still printed '100% complete'.
A11: SO: WHAT DO WE ACTUALLY KNOW?
A12: Only legislation has ever been compared against the publisher's own list of what they published. That comparison — a 'walk' — is the only thing that produces a real percentage.
A13: MEASURED 7 sources. A publisher walk exists. The percentage is a fact.
A14: CLAIMED 5 sources. A target exists but nobody can say where it came from.
A15: UNMEASURED 59 sources. No denominator. NO PERCENTAGE IS SHOWN. That blank is the honest answer.
... A53: 5. Quality, not volume: 131,654 tribunal rows are landing pages; 28,629 sections from three retired collections are still being served.

Sheet Master Register
A1: ID | B1: Tier | C1: Source | D1: Corpus key | E1: Status | F1: New? | G1: Publisher | H1: Unit (what the publisher counts) | I1: Units published | J1: Units held | K1: % complete (units) | L1: Sections held | M1: Words held (V30 snapshot) | N1: Coverage state | O1: Licence code | P1: Licence status | Q1: Commercial use OK? | R1: Priority | S1: Known issue — what is wrong | T1: Work to close it | U1: Why this matters
A2: L01 | B2: T1 The law itself | C2: UK Public General Acts 2000 to date | D2: primary-acts-2000plus | E2: HELD | G2: legislation.gov.uk (TNA) | H2: Act | I2: 938 | J2: 933 | K2: =IFERROR(J2/I2,"") -> 0.99466951 | L2: 147788 | M2: 22001014 | N2: MEASURED | O2: ogl-3.0 | P2: CLEAR | Q2: Yes | R2: 1 | S2: 5 Acts published but not held. | T2: Fetch the 5 from the v36 worklist. | U2: The current statute book. Non-negotiable core.
A3: L02 | B3: T1 The law itself | C3: UK Public General Acts 1801–1999 | D3: primary-acts-pre-2000 | E3: HELD | G3: legislation.gov.uk (TNA) | H3: Act | I3: 9343 | J3: 3560 | K3: =IFERROR(J3/I3,"") -> 0.38103393 | L3: 166290 | M3: 24783975 | N3: MEASURED | O3: ogl-3.0 | P3: CLEAR | Q3: Yes | R3: 1 | S3: 5,783 Acts with text at source are not held. A further 7,279 published Acts carry no provisions and are correctly excluded. ~11.4% of held legislation sections are one-word dot-leaders (the source's rendering of a repealed provision). | T3: Fetch the 5,783 from scripts/ingest/v36/worklist.jsonl. Flag dot-leaders, do not delete. | U3: Historic statute is what makes 'is this still law?' answerable. The weakest part of the corpus.
A4: L03 | B4: T1 The law itself | C4: UK Statutory Instruments to 2009 | D4: si-pre-2010 | E4: HELD | G4: legislation.gov.uk (TNA) | H4: SI | I4: see L04 | J4: see L04 | L4: 462809 | M4: 61581830 | N4: MEASURED | O4: ogl-3.0 | P4: CLEAR | Q4: Yes | R4: 1 | S4: The uksi walk is a single figure across both SI collections; it has never been split by year. | T4: Split the uksi year walk so each SI collection gets its own denominator. | U4: Most law that binds people is secondary, not primary.
A5: L04 | B5: T1 The law itself | C5: UK Statutory Instruments 2010 to date | D5: si-2010plus | E5: HELD | G5: legislation.gov.uk (TNA) | H5: SI | I5: 100971 | J5: 73558 | K5: =IFERROR(J5/I5,"") -> 0.7285062 | L5: 275744 | M5: 40102967 | N5: MEASURED | O5: ogl-3.0 | P5: CLEAR | Q5: Yes | R5: 1 | S5: Figures are BOTH SI collections combined. 27,413 SIs with text are not held; 8,219 more carry no provisions. | T5: Fetch the 27,413 from the v36 worklist. | U5: As L03.
A6: L05 | B6: T1 The law itself | C6: Retained / assimilated EU law | D6: retained-eu | E6: HELD | G6: legislation.gov.uk (TNA) | H6: instrument | I6: 46150 | J6: 39068 | K6: =IFERROR(J6/I6,"") -> 0.84654388 | L6: 199224 | M6: 18991303 | N6: MEASURED | O6: ogl-3.0+eu-2011-833 | P6: CLEAR | Q6: Yes | R6: 1 | S6: 7,082 instruments with text not held. 113,623 further published instruments carry no provisions. | T6: Fetch the 7,082 from the v36 worklist. | U6: Post-Brexit statute book depends on knowing what was retained.
A7: L06 | B7: T1 The law itself | C7: Devolved primary + secondary legislation (asp, ssi, anaw/asc, wsi, nia, nisr) | D7: regional | E7: HELD | G7: legislation.gov.uk (TNA) | H7: instrument | I7: 38099 | J7: 26150 | K7: =IFERROR(J7/I7,"") -> 0.68636972 | L7: 341093 | M7: 45623780 | N7: MEASURED | O7: ogl-3.0 | P7: CLEAR | Q7: Yes | R7: 1 | S7: Figure is a residual (all types minus ukpga, uksi, eur) — never printed per type. 1,630 recoverable instruments absent. | T7: Split the walk by type; fetch the 1,630. | U7: Three legislatures make law Westminster does not.
A8: L07 | B8: T1 The law itself | C8: Explanatory Notes to Acts | D8: explanatory-notes | E8: HELD | G8: legislation.gov.uk (TNA) | H8: Act with an EN | I8: not walked | L8: 18651 | M8: 9173040 | N8: UNMEASURED | O8: ogl-3.0 | P8: CLEAR | Q8: Yes | R8: 2 | S8: Old target was 410 against 18,651 held — 4,549% — and the email still printed 100% complete. | T8: Walk: count instruments carrying an EN link at source. | U8: ENs state Parliament's intention. Lex leans on them heavily.
A9: L08 | B9: T1 The law itself | C9: Explanatory Memoranda to SIs | D9: explanatory-memoranda | E9: HELD | G9: legislation.gov.uk (TNA) | H9: SI with an EM | I9: not walked | L9: 21984 | M9: 13515324 | N9: UNMEASURED | O9: ogl-3.0 | P9: CLEAR | Q9: Yes | R9: 2 | S9: Old target 5,420 against 21,984 held — 406%. | T9: Walk: count SIs carrying an EM at source. | U9: The only plain-English account of what an SI does.
A10: L09 | B10: T1 The law itself | C10: Impact Assessments | D10: impact-assessments | E10: PARTIAL | G10: legislation.gov.uk (TNA) | H10: impact assessment | I10: 18759 | J10: 18756 | K10: =IFERROR(J10/I10,"") -> 0.99984008 | L10: 18756 | N10: CLAIMED | O10: ogl-3.0 | P10: CLEAR | Q10: Yes | R10: 2 | S10: 3 absent. Provenance of the 18,759 figure unproven. ~1,235 post-legislative review documents sit inside this collection and cannot be separated out. | T10: Fetch 3; prove the denominator; split out post-legislative memoranda. | U10: Evidence base behind each Bill.
A11: L10 | B11: T1 The law itself | C11: Acts of the Parliament of Northern Ireland 1921–1972 | D11: apni | E11: NOT STARTED | G11: legislation.gov.uk (TNA) | H11: Act | I11: not walked | J11: 0 | L11: 0 | N11: NOT STARTED | O11: ogl-3.0 | P11: CLEAR | Q11: Yes | R11: 1 | S11: Nothing held. 2,602 inbound citations in the corpus point at legislation we do not have. | T11: Build the apni seeder. | U11: Cited 2,602 times by law we DO hold — every one of those is a dead link today.
A12: L11 | B12: T1 The law itself | C12: Church Measures | D12: ukcm | E12: NOT STARTED | G12: legislation.gov.uk (TNA) | H12: Measure | I12: not walked | J12: 0 | L12: 0 | N12: NOT STARTED | O12: ogl-3.0 | P12: CLEAR | Q12: Yes | R12: 1 | S12: Nothing held. 6,803 inbound citations point at it. | T12: Build the ukcm seeder. | U12: Measures have the force of an Act. 6,803 dead citations.
A13: L12 | B13: T1 The law itself | C13: Church Instruments | D13: ukci | E13: NOT STARTED | G13: legislation.gov.uk (TNA) | H13: instrument | I13: not walked | J13: 0 | L13: 0 | N13: NOT STARTED | O13: ogl-3.0 | P13: CLEAR | Q13: Yes | R13: 3 | S13: Nothing held. | T13: Build the ukci seeder. | U13: Completes the legislation.gov.uk type list.
A14: L13 | B14: T1 The law itself | C14: Local and Private Acts | D14: ukla | E14: NOT STARTED | G14: legislation.gov.uk (TNA) | H14: Act | I14: not walked | J14: 0 | L14: 0 | N14: NOT STARTED | O14: ogl-3.0 | P14: CLEAR | Q14: Yes | R14: 2 | S14: No target row and no seeder has ever existed. | T14: Create target + seeder. | U14: Ports, railways, universities, City of London — private Acts still bind. Plan estimated ~10,000 sections.
A15: L14 | B15: T1 The law itself | C15: Pre-1801 statute (Statutes of the Realm; Acts of the Parliament of Scotland pre-1707; Irish Acts) | D15: pre-1801-statute | E15: NOT STARTED | F15: NEW | G15: legislation.gov.uk + TNA + BAILII | H15: Act | I15: not walked | J15: 0 | L15: 0 | N15: NOT STARTED | O15: ogl-3.0 | P15: UNVERIFIED | Q15: Unknown | R15: 3 | S15: Not in the plan at all. legislation.gov.uk carries some pre-1801 Acts (Magna Carta, Bill of Rights) but coverage is partial. | T15: Scope what legislation.gov.uk actually holds pre-1801; identify the gap. | U15: Constitutional statutes that are still in force and still argued in court.
A16: L15 | B16: T1 The law itself | C16: Legacy LegislationSection table | D16: legacy-legislation-section | E16: RETIRED | G16: internal | H16: section | J16: 0 | L16: 914274 | N16: LEGACY | O16: ogl-3.0 | P16: CLEAR | Q16: Yes | R16: 1 | S16: 914,274 sections across 127,790 instruments sitting in the old table, reachable by no search path. Overlap with corpus_sections and the worklist has never been joined. | T16: Join legacy ids to corpus_sections and to the worklist; report how many are in NEITHER. That number decides whether this matters at all. | U16: Either a large hidden gap or a large duplicate. Nobody currently knows which.
A17: P01 | B17: T2 Parliament (Westminster) | C17: Hansard — Commons debates (modern) | D17: pwdata-debates | E17: HELD | G17: TheyWorkForYou / ParlParse | H17: sitting-day file | I17: not walked | L17: 6387304 | M17: 1012382550 | N17: UNMEASURED | O17: opl-3.0 | P17: CLEAR | Q17: Yes | R17: 1 | S17: Largest single collection. No publisher walk. Overlaps historic-hansard and is not de-duplicated in retrieval. | T17: Walk the scrapedxml directory index; report missing days. | U17: The record of what Parliament said. Core to every Scrutinise answer.
A18: P02 | B18: T2 Parliament (Westminster) | C18: Hansard — historic (1803–2005) | D18: historic-hansard | E18: HELD | G18: api.parliament.uk historic-hansard | H18: House + date | I18: not walked | L18: 4641085 | M18: 783216544 | N18: UNMEASURED | O18: opl-3.0 | P18: CLEAR | Q18: Yes | R18: 1 | S18: No walk. Known overlap window with pwdata-debates / pwdata-lords, not de-duplicated. | T18: Walk the sittings index; measure and resolve the overlap. | U18: 200 years of debate. Where the intention behind old Acts lives.
A19: P03 | B19: T2 Parliament (Westminster) | C19: Written Answers — Commons | D19: pwdata-wrans | E19: HELD | G19: TheyWorkForYou / ParlParse | H19: sitting-day file | I19: not walked | L19: 1232999 | M19: 180642434 | N19: UNMEASURED | O19: opl-3.0 | P19: CLEAR | Q19: Yes | R19: 2 | S19: No walk. | T19: Walk. | U19: Ministers' own account of how a policy operates.
A20: P04 | B20: T2 Parliament (Westminster) | C20: Hansard — Lords debates | D20: pwdata-lords | E20: HELD | G20: TheyWorkForYou / ParlParse | H20: sitting-day file | I20: not walked | L20: 752805 | M20: 211590640 | N20: UNMEASURED | O20: opl-3.0 | P20: CLEAR | Q20: Yes | R20: 1 | S20: No walk. | T20: Walk. | U20: Where most Bill scrutiny actually happens.
A21: P05 | B21: T2 Parliament (Westminster) | C21: Committee reports | D21: committees-reports | E21: HELD | G21: committees.parliament.uk | H21: publication | I21: not walked | L21: 323922 | M21: 70980271 | N21: UNMEASURED | O21: opl-3.0 | P21: CLEAR | Q21: Yes | R21: 1 | S21: Old target 24,876 against 323,922 held — 1,302% — printed as 100% complete. | T21: Walk the committees publications API. | U21: Select committee reports are the main pre-legislative evidence base.
A22: P06 | B22: T2 Parliament (Westminster) | C22: Westminster Hall debates | D22: pwdata-westminster | E22: HELD | G22: TheyWorkForYou / ParlParse | H22: sitting-day file | I22: not walked | L22: 239262 | M22: 83774185 | N22: UNMEASURED | O22: opl-3.0 | P22: CLEAR | Q22: Yes | R22: 2 | S22: No walk. | T22: Walk. | U22: Backbench debates on emerging issues.
A23: P07 | B23: T2 Parliament (Westminster) | C23: Written Answers — Lords | D23: pwdata-lordswrans | E23: HELD | G23: TheyWorkForYou / ParlParse | H23: sitting-day file | I23: not walked | L23: 175592 | M23: 27526245 | N23: UNMEASURED | O23: opl-3.0 | P23: CLEAR | Q23: Yes | R23: 2 | S23: 1 failed fetch (HTTP 503, retryable). | T23: Walk; retry the failure. | U23: As P03.
A24: P08 | B24: T2 Parliament (Westminster) | C24: Committee oral + written evidence | D24: committees-evidence | E24: HELD | G24: committees.parliament.uk | H24: evidence item | I24: not walked | L24: 140567 | M24: 508343362 | N24: UNMEASURED | O24: opl-3.0 | P24: CLEAR | Q24: Yes | R24: 1 | S24: No walk. | T24: Walk. | U24: The raw testimony behind the reports — often more useful than the report.
A25: P09 | B25: T2 Parliament (Westminster) | C25: Commons oral questions (Linked Data API) | D25: lda-commonsoralquestions | E25: HELD | G25: data.parliament.uk (LDA) | H25: question | I25: not walked | L25: 69529 | M25: 2004846 | N25: UNMEASURED | O25: opl-3.0 | P25: CLEAR | Q25: Yes | R25: 3 | S25: The LDA service is scheduled for retirement. | T25: Confirm the service still answers; plan a migration to the modern API. | U25: Ministerial accountability on the floor.
A26: P10 | B26: T2 Parliament (Westminster) | C26: Early Day Motions | D26: early-day-motions | E26: HELD | G26: edm.parliament.uk | H26: motion | I26: not walked | L26: 60737 | M26: 8085150 | N26: UNMEASURED | O26: opl-3.0 | P26: CLEAR | Q26: Yes | R26: 3 | S26: No walk. | T26: Walk. | U26: Cheap signal of backbench opinion — feeds the position graph.
A27: P11 | B27: T2 Parliament (Westminster) | C27: e-Petitions (open + archived) | D27: petitions | E27: PARTIAL | G27: petition.parliament.uk | H27: petition | I27: not walked | L27: 49529 | M27: 6244101 | N27: UNMEASURED | O27: ogl-3.0 | P27: CLEAR | Q27: Yes | R27: 2 | S27: Internal estimate ~66,075 (75%) — an internal guess, not a publisher figure. | T27: Walk the JSON API for a real denominator. | U27: Direct public demand for legislative change. Central to Scrutinise's mission.
A28: P12 | B28: T2 Parliament (Westminster) | C28: Written Ministerial Statements — Commons | D28: pwdata-wms | E28: HELD | G28: TheyWorkForYou / ParlParse | H28: sitting-day file | I28: not walked | L28: 23863 | M28: 10223233 | N28: UNMEASURED | O28: opl-3.0 | P28: CLEAR | Q28: Yes | R28: 3 | S28: No walk. | T28: Walk. | U28: How policy changes are announced without debate.
... A32: P16 | B32: T2 Parliament (Westminster) | C32: Register of Members' Financial Interests | D32: members-interests | E32: HELD | G32: Parliament interests API | H32: register entry | I32: not walked | L32: 3448 | M32: 42435 | N32: UNMEASURED | O32: opl-3.0 | P32: CLEAR | Q32: Yes | R32: 3 | S32: No walk. | T32: Walk. | U32: Conflict-of-interest context on any position.
A33: P17 | B33: T2 Parliament (Westminster) | C33: Lords division votes (per member) | D33: lords-divisions-votes | E33: HELD | G33: Parliament votes API | H33: division | I33: not walked | L33: 3284 | N33: UNMEASURED | O33: opl-3.0 | P33: CLEAR | Q33: Yes | R33: 2 | S33: Possible duplicate of lda-lordsdivisions. | T33: Walk; resolve duplication. | U33: 2.5M vote edges in the position graph rest on this.
A34: P18 | B34: T2 Parliament (Westminster) | C34: Commons division votes (per member) | D34: commons-divisions-votes | E34: HELD | G34: Parliament votes API | H34: division | I34: not walked | L34: 2361 | N34: UNMEASURED | O34: opl-3.0 | P34: CLEAR | Q34: Yes | R34: 2 | S34: Possible duplicate of lda-commonsdivisions. | T34: Walk; resolve duplication. | U34: As P17.
A35: P19 | B35: T2 Parliament (Westminster) | C35: Lords divisions (Linked Data API) | D35: lda-lordsdivisions | E35: HELD | G35: data.parliament.uk (LDA) | H35: division | I35: not walked | L35: 2089 | M35: 17753 | N35: UNMEASURED | O35: opl-3.0 | P35: CLEAR | Q35: Yes | R35: 3 | S35: Possible duplicate of lords-divisions-votes. | T35: Walk; resolve duplication. | U35: As P17.
A36: P20 | B36: T2 Parliament (Westminster) | C36: Erskine May | D36: erskine-may | E36: PARTIAL | G36: erskinemay.parliament.uk | H36: paragraph | I36: 2038 | J36: 1873 | K36: =IFERROR(J36/I36,"") -> 0.91903827 | L36: 1873 | M36: 589373 | N36: CLAIMED | O36: opl-3.0 | P36: UNVERIFIED | Q36: Unknown | R36: 2 | S36: 165 paragraphs short. Provenance of the 2,038 figure unproven. Access described as 'partial' in the plan. | T36: Finish; prove the denominator; verify the licence. | U36: The rulebook for how Parliament handles a Bill. Directly useful to a reformer.
A37: P21 | B37: T2 Parliament (Westminster) | C37: Written answers (legacy collection) | D37: written-answers | E37: HELD | G37: Parliament API | H37: file | I37: not walked | L37: 143 | M37: 43748825 | N37: UNMEASURED | O37: opl-3.0 | P37: CLEAR | Q37: Yes | R37: 2 | S37: 143 rows at roughly 306,000 words each — whole files stored as single sections. Unretrievable at this granularity. | T37: Re-split into per-answer sections. | U37: Broken, not missing. Fixing it is cheap.
A38: P22 | B38: T2 Parliament (Westminster) | C38: Bill amendment papers, marshalled lists and notices of amendments | D38: bill-amendments | E38: NOT STARTED | F38: NEW | G38: bills.parliament.uk / publications.parliament.uk | H38: amendment paper | I38: not walked | J38: 0 | L38: 0 | N38: NOT STARTED | O38: opl-3.0 | P38: CLEAR | Q38: Yes | R38: 1 | S38: Not in the plan. Bills-api holds stage metadata, not the amendment text. | T38: Create target + seeder from the Bills API publications endpoint. | U38: THE most directly useful missing source for Scrutinise. An amendment is exactly the artefact a user is trying to produce. Without these, Lex cannot show a user what a real amendment looks like or whether theirs has been tried before.
A39: P23 | B39: T2 Parliament (Westminster) | C39: Public Bill Committee evidence | D39: pbc-evidence | E39: NOT STARTED | F39: NEW | G39: committees.parliament.uk | H39: evidence item | I39: not walked | J39: 0 | L39: 0 | N39: NOT STARTED | O39: opl-3.0 | P39: CLEAR | Q39: Yes | R39: 2 | S39: May be partly inside committees-evidence; never separated. | T39: Determine overlap with committees-evidence, then seed the remainder. | U39: Evidence given directly on a live Bill — the highest-value moment to intervene.
A40: P24 | B40: T2 Parliament (Westminster) | C40: Delegated Powers and Regulatory Reform Committee (DPRRC) reports | D40: dprrc | E40: NOT STARTED | F40: NEW | G40: committees.parliament.uk | H40: report | I40: not walked | J40: 0 | L40: 0 | N40: NOT STARTED | O40: opl-3.0 | P40: CLEAR | Q40: Yes | R40: 2 | S40: May be inside committees-reports; never separated. | T40: Separate out as its own collection. | U40: The committee that judges whether a Bill hands Ministers too much power. Core scrutiny doctrine.
A41: P25 | B41: T2 Parliament (Westminster) | C41: Joint Committee on Statutory Instruments (JCSI) + Secondary Legislation Scrutiny Committee (SLSC) reports | D41: si-scrutiny | E41: NOT STARTED | F41: NEW | G41: committees.parliament.uk | H41: report | I41: not walked | J41: 0 | L41: 0 | N41: NOT STARTED | O41: opl-3.0 | P41: CLEAR | Q41: Yes | R41: 2 | S41: May be inside committees-reports; never separated. | T41: Separate out as its own collection. | U41: The only systematic scrutiny SIs receive. Directly answers 'was this SI challenged?'
A42: P26 | B42: T2 Parliament (Westminster) | C42: Command Papers (White Papers, Green Papers, Government responses, treaty CPs) | D42: command-papers | E42: NOT STARTED | F42: NEW | G42: gov.uk + parliament.uk | H42: Command Paper | I42: not walked | J42: 0 | L42: 0 | N42: NOT STARTED | O42: ogl-3.0 | P42: CLEAR | Q42: Yes | R42: 2 | S42: Plan row 38 existed for White/Green Papers but no target row was created. The 175-section govuk-core-docs collection stands in for this and three other plan rows. | T42: Create a proper command-papers collection; walk the numbered CP series. | U42: A numbered, complete official series. The policy intention behind almost every Bill.
A43: P27 | B43: T2 Parliament (Westminster) | C43: House of Commons Library briefings | D43: commons-library | E43: NOT STARTED | G43: commonslibrary.parliament.uk | H43: briefing | I43: not walked | J43: 0 | L43: 0 | N43: NOT STARTED | O43: opl-3.0 | P43: CLEAR | Q43: Yes | R43: 2 | S43: Plan row 39; no target row ever created. | T43: Create target + seeder. | U43: Neutral, expert, plain-English summaries of every Bill. The single best explanatory layer available.
...

Sheet Coverage Summary
A1: COVERAGE SUMMARY
A2: Every figure below is a live formula over the Master Register tab. Change a number there and this updates.
A4: PART 1 — THE ONE THING WE CAN PROVE: UK LEGISLATION
A6: Category | B6: Held | C6: Published | D6: No text at source | E6: Denominator with text | F6: % of all published | G6: % of those with text
A7: UK Public General Acts, 2000 to date | B7: 933 | C7: 938 | D7: 0 | E7: =C7-D7 -> 938 | F7: =B7/C7 -> 0.99466951 | G7: =IFERROR(B7/E7,"") -> 0.99466951
A8: UK Public General Acts, 1801–1999 | B8: 3560 | C8: 16622 | D8: 7279 | E8: =C8-D8 -> 9343 | F8: =B8/C8 -> 0.21417399 | G8: =IFERROR(B8/E8,"") -> 0.38103393
A9: UK Statutory Instruments, all years | B9: 73558 | C9: 109190 | D9: 8219 | E9: =C9-D9 -> 100971 | F9: =B9/C9 -> 0.67366975 | G9: =IFERROR(B9/E9,"") -> 0.7285062
A10: Retained / assimilated EU law | B10: 39068 | C10: 159773 | D10: 113623 | E10: =C10-D10 -> 46150 | F10: =B10/C10 -> 0.24452192 | G10: =IFERROR(B10/E10,"") -> 0.84654388
A11: Devolved, local and church legislation | B11: 26150 | C11: 38099 | D11: 10319 | E11: =C11-D11 -> 27780 | F11: =B11/C11 -> 0.68636972 | G11: =IFERROR(B11/E11,"") -> 0.94132469
A12: ALL UK LEGISLATION | B12: =SUM(B7:B11) -> 143269 | C12: =SUM(C7:C11) -> 324622 | D12: =SUM(D7:D11) -> 139440 | E12: =C12-D12 -> 185182 | F12: =B12/C12 -> 0.44134101 | G12: =B12/E12 -> 0.77366591
A13: Instruments published, with text, that we do NOT hold — the recoverable work list | B13: =E12-B12 -> 41913 | G13: Already enumerated in scripts/ingest/v36/worklist.jsonl. Nothing needs discovering; it needs fetching.
A15: PART 2 — HOW MUCH OF THE REST DO WE KNOW ANYTHING ABOUT?
A16: Coverage state | B16: Sources | C16: Sections held | G16: What it means
A17: MEASURED | B17: =COUNTIF('Master Register'!$N$2:$N$126,A17) -> 7 | C17: =SUMIF('Master Register'!$N$2:$N$126,A17,'Master Register'!$L$2:$L$126) -> 1593298 | G17: A publisher walk exists. The percentage is a fact.
A18: CLAIMED | B18: =COUNTIF('Master Register'!$N$2:$N$126,A18) -> 5 | C18: =SUMIF('Master Register'!$N$2:$N$126,A18,'Master Register'!$L$2:$L$126) -> 81772 | G18: A target exists but its provenance is unproven. Treat as unmeasured until checked.
A19: UNMEASURED | B19: =COUNTIF('Master Register'!$N$2:$N$126,A19) -> 59 | C19: =SUMIF('Master Register'!$N$2:$N$126,A19,'Master Register'!$L$2:$L$126) -> 16568736 | G19: No denominator. No percentage is shown — and that blank is the honest answer.
A20: NOT STARTED | B20: =COUNTIF('Master Register'!$N$2:$N$126,A20) -> 42 | C20: =SUMIF('Master Register'!$N$2:$N$126,A20,'Master Register'!$L$2:$L$126) -> 0 | G20: Nothing held at all.
A21: BLOCKED | B21: =COUNTIF('Master Register'!$N$2:$N$126,A21) -> 1 | C21: =SUMIF('Master Register'!$N$2:$N$126,A21,'Master Register'!$L$2:$L$126) -> 0 | G21: Cannot be taken — licence-hostile.
A22: RETIRED | B22: =COUNTIF('Master Register'!$N$2:$N$126,A22) -> 3 | C22: =SUMIF('Master Register'!$N$2:$N$126,A22,'Master Register'!$L$2:$L$126) -> 28629 | G22: Superseded, but the rows were never deleted and are still served.
A23: LEGACY | B23: =COUNTIF('Master Register'!$N$2:$N$126,A23) -> 1 | C23: =SUMIF('Master Register'!$N$2:$N$126,A23,'Master Register'!$L$2:$L$126) -> 914274 | G23: Held in the old table; no search path reaches it.
A24: OUT OF SCOPE | B24: =COUNTIF('Master Register'!$N$2:$N$126,A24) -> 7 | C24: =SUMIF('Master Register'!$N$2:$N$126,A24,'Master Register'!$L$2:$L$126) -> 0 | G24: Private intellectual property. Cite by reference only.
A25: TOTAL (excluding the legacy table, which is not in corpus_sections) | B25: =SUM(B17:B24) -> 125 | C25: =SUM(C17:C24)-C23 -> 18272435
A27: PART 3 — BY TIER
A28: Tier | B28: Sources | C28: Sections held | D28: Of which NOT STARTED | E28: New proposals
A29: O Out of scope (private IP) | B29: =COUNTIF('Master Register'!$B$2:$B$126,A29) -> 7 | C29: =SUMIF('Master Register'!$B$2:$B$126,A29,'Master Register'!$L$2:$L$126) -> 0 | D29: =COUNTIFS('Master Register'!$B$2:$B$126,A29,'Master Register'!$E$2:$E$126,"NOT STARTED") -> 0 | E29: =COUNTIFS('Master Register'!$B$2:$B$126,A29,'Master Register'!$F$2:$F$126,"NEW") -> 0
A30: T1 The law itself | B30: =COUNTIF('Master Register'!$B$2:$B$126,A30) -> 15 | C30: =SUMIF('Master Register'!$B$2:$B$126,A30,'Master Register'!$L$2:$L$126) -> 2566613 | D30: =COUNTIFS('Master Register'!$B$2:$B$126,A30,'Master Register'!$E$2:$E$126,"NOT STARTED") -> 5 | E30: =COUNTIFS('Master Register'!$B$2:$B$126,A30,'Master Register'!$F$2:$F$126,"NEW") -> 1
A31: T2 Parliament (Westminster) | B31: =COUNTIF('Master Register'!$B$2:$B$126,A31) -> 30 | C31: =SUMIF('Master Register'!$B$2:$B$126,A31,'Master Register'!$L$2:$L$126) -> 14143412 | D31: =COUNTIFS('Master Register'!$B$2:$B$126,A31,'Master Register'!$E$2:$E$126,"NOT STARTED") -> 9 | E31: =COUNTIFS('Master Register'!$B$2:$B$126,A31,'Master Register'!$F$2:$F$126,"NEW") -> 8
A32: T3 Courts & tribunals | B32: =COUNTIF('Master Register'!$B$2:$B$126,A32) -> 12 | C32: =SUMIF('Master Register'!$B$2:$B$126,A32,'Master Register'!$L$2:$L$126) -> 405622 | D32: =COUNTIFS('Master Register'!$B$2:$B$126,A32,'Master Register'!$E$2:$E$126,"NOT STARTED") -> 6 | E32: =COUNTIFS('Master Register'!$B$2:$B$126,A32,'Master Register'!$F$2:$F$126,"NEW") -> 4
A33: T4 Devolved legislatures | B33: =COUNTIF('Master Register'!$B$2:$B$126,A33) -> 4 | C33: =SUMIF('Master Register'!$B$2:$B$126,A33,'Master Register'!$L$2:$L$126) -> 1431342 | D33: =COUNTIFS('Master Register'!$B$2:$B$126,A33,'Master Register'!$E$2:$E$126,"NOT STARTED") -> 1 | E33: =COUNTIFS('Master Register'!$B$2:$B$126,A33,'Master Register'!$F$2:$F$126,"NEW") -> 1
A34: T5 Government, regulators & guidance | B34: =COUNTIF('Master Register'!$B$2:$B$126,A34) -> 38 | C34: =SUMIF('Master Register'!$B$2:$B$126,A34,'Master Register'!$L$2:$L$126) -> 341112 | D34: =COUNTIFS('Master Register'!$B$2:$B$126,A34,'Master Register'!$E$2:$E$126,"NOT STARTED") -> 15 | E34: =COUNTIFS('Master Register'!$B$2:$B$126,A34,'Master Register'!$F$2:$F$126,"NEW") -> 12
A35: T6 EU & international | B35: =COUNTIF('Master Register'!$B$2:$B$126,A35) -> 12 | C35: =SUMIF('Master Register'!$B$2:$B$126,A35,'Master Register'!$L$2:$L$126) -> 269979 | D35: =COUNTIFS('Master Register'!$B$2:$B$126,A35,'Master Register'!$E$2:$E$126,"NOT STARTED") -> 2 | E35: =COUNTIFS('Master Register'!$B$2:$B$126,A35,'Master Register'!$F$2:$F$126,"NEW") -> 1
A36: T7 Local government | B36: =COUNTIF('Master Register'!$B$2:$B$126,A36) -> 4 | C36: =SUMIF('Master Register'!$B$2:$B$126,A36,'Master Register'!$L$2:$L$126) -> 0 | D36: =COUNTIFS('Master Register'!$B$2:$B$126,A36,'Master Register'!$E$2:$E$126,"NOT STARTED") -> 4 | E36: =COUNTIFS('Master Register'!$B$2:$B$126,A36,'Master Register'!$F$2:$F$126,"NEW") -> 4
A37: X Retired but still serving | B37: =COUNTIF('Master Register'!$B$2:$B$126,A37) -> 3 | C37: =SUMIF('Master Register'!$B$2:$B$126,A37,'Master Register'!$L$2:$L$126) -> 28629 | D37: =COUNTIFS('Master Register'!$B$2:$B$126,A37,'Master Register'!$E$2:$E$126,"NOT STARTED") -> 0 | E37: =COUNTIFS('Master Register'!$B$2:$B$126,A37,'Master Register'!$F$2:$F$126,"NEW") -> 0
A38: TOTAL (excluding the legacy table) | B38: =SUM(B29:B37) -> 125 | C38: =SUM(C29:C37)-914274 -> 18272435 | D38: =SUM(D29:D37) -> 42 | E38: =SUM(E29:E37) -> 31

Sheet Licences & Letters
A1: ID | B1: Source | C1: Corpus key(s) | D1: Licence code | E1: Licence status | F1: Commercial use OK? | G1: Verified | H1: What the licence actually says | I1: Risk to us — plain English | J1: CHARLIE ACTION — what to write | K1: Write to | L1: Urgency
A2: LIC01 | B2: Find Case Law (senior court judgments) | C2: tna-caselaw | D2: ojl-2.0 | E2: ACTION — WE ARE OUTSIDE THE LICENCE TODAY | F2: No — not without a further licence | G2: 12 Jun 2026 | H2: Open Justice Licence v2.0 permits reading and reproduction but EXPRESSLY EXCLUDES computational analysis — which the licence defines to include search indexing, bulk processing and machine learning. | I2: HIGH. We hold 74,896 judgments, have embedded them into a vector index and serve them through full-text search. That is computational analysis. This is not a future risk; it is the current state. | J2: Write to The National Archives applying for the separate computational-analysis licence. Explain: non-profit civic-technology platform, purpose is public legal understanding and legislative scrutiny, no redistribution of judgment text, attribution carried per section. | K2: caselawlicence@nationalarchives.gov.uk | L2: DO FIRST
A3: LIC02 | B3: BAILII — case law before 2001 | C3: bailii-pre-2001 (planned) | D3: BAILII terms | E3: ACTION — needed BEFORE the fetch | F3: Unknown | G3: not yet verified | H3: BAILII is a small charity. Its terms restrict systematic downloading and it has historically asked bulk users to make contact and contribute. | I3: HIGH if we start a 150,000+ judgment crawl unannounced. A blocked IP costs more than a week, and the reputational cost to a civic-tech project is worse. | J3: Write to BAILII BEFORE any bulk run: describe the project, the rate we propose (slow), offer attribution and a donation. Ask which databases we may and may not take. | K3: enquiries@bailii.org | L3: DO FIRST — gates the largest gap in the corpus
A4: LIC03 | B4: FCA Handbook | C4: fca-handbook | D4: fca-restricted | E4: ACTION — WE ARE OUTSIDE THE LICENCE TODAY | F4: No | G4: 12 Jun 2026 | H4: Reproduction, or storage in any retrieval system, requires the FCA's prior written permission. Reproducing the Handbook requires a licence agreement. | I4: HIGH. 3,661 sections are stored and indexed now. Any backfill toward the 150,000-section estimate multiplies the exposure. | J4: Write to the FCA requesting a Handbook licence for a non-commercial research and public-understanding platform. Ask explicitly whether indexing for search is covered. | K4: FCA — via fca.org.uk/contact, marked for the Handbook / legal team | L4: DO FIRST — gates a 146,000-section backfill
A5: LIC04 | B5: National Audit Office reports | C5: nao-reports | D5: nao-nc | E5: RESTRICTED — non-commercial only | F5: No | G5: 12 Jun 2026 | H5: Free re-use for non-commercial purposes with attribution. Commercial use requires express permission. | I5: MEDIUM. Fine for Scrutinise as a not-for-profit. Becomes a blocker the day a commercial arm launches. | J5: No action needed now. If a commercial arm is created, write to the NAO for permission. Flag the rows as commercial-excluded in the meantime. | K5: NAO — enquiries@nao.org.uk | L5: Before any commercial launch
A6: LIC05 | B6: ECtHR judgments (HUDOC) | C6: echr-hudoc | D6: echr-nc | E6: RESTRICTED — non-commercial only | F6: No | G6: 13 Jun 2026 | H6: Free reproduction with acknowledgment for private, information or education purposes. Commercial use requires prior written permission. | I6: MEDIUM. Same shape as the NAO position. | J6: No action now; write for commercial permission before any commercial launch. | K6: Council of Europe — publishing@echr.coe.int | L6: Before any commercial launch
A7: LIC06 | B7: OECD publications | C7: oecd | D7: cc-by-nc-4.0 (pre-Jul-2024) / cc-by-4.0 (post-Jul-2024) | E7: SPLIT — depends on publication date | F7: Partial | G7: V19 | H7: OECD content published before July 2024 is CC-BY-NC (non-commercial). Content published from July 2024 is CC-BY and freely usable including commercially. | I7: LOW, but the two vintages must be labelled separately or the whole collection has to be treated as non-commercial. | J7: No letter needed. Ask CC to date-split the 505 held rows and label them. | K7: — | L7: Housekeeping
A8: LIC07 | B8: IMF data | C8: (licence register entry) | D8: commercialUseExcluded=true | E8: RESTRICTED | F8: No | G8: recorded in register | H8: Commercial use excluded. The first such entry in the licence register. | I8: LOW while non-profit. | J8: None now. | K8: — | L8: Before any commercial launch
A9: LIC08 | B9: College of Policing APP | C9: college-of-policing | D9: pending-verification | E9: UNVERIFIED — cannot read the terms | F9: Unknown | G9: blocked | H9: The terms and conditions page is behind Cloudflare and cannot be read by our crawler. A footer grep is NOT verification — that rule is already in the playbook. | I9: MEDIUM. We hold 332 sections under an unknown licence and Charlie has asked for a large backfill of this source. | J9: Write to the College of Policing asking for the re-use terms for Authorised Professional Practice in writing. | K9: College of Policing — contactus@college.police.uk | L9: Before the APP backfill
A10: LIC09 | B10: Northern Ireland judgments | C10: ni-judgments | D10: pending-verification | E10: UNVERIFIED — Crown copyright asserted, no open licence stated | F10: Unknown | G10: 12 Jun 2026 | H10: The site asserts Crown copyright but states no open licence. Judgment sources are being treated cautiously given the Find Case Law precedent. | I10: MEDIUM. 7,772 judgments held. | J10: Write to the Judicial Studies Board / Lady Chief Justice's Office in Belfast asking for written re-use terms. | K10: Judiciary NI — via judiciaryni.uk contact form | L10: Within the census sprint
A11: LIC10 | B11: Tax tribunal decisions | C11: tax-tribunals | D11: pending-verification | E11: UNVERIFIED — no statement found | F11: Unknown | G11: 12 Jun 2026 | H11: No licence statement on the HMCTS legacy site. | I11: MEDIUM. 12,089 decisions held. | J11: Write to HMCTS asking for the re-use position on published tribunal decisions. | K11: HMCTS — via gov.uk contact | L11: Within the census sprint
A12: LIC11 | B12: Northern Ireland Law Commission | C12: nilawcom | D12: pending-verification | E12: UNVERIFIED — site SSL certificate dead | F12: Unknown | G12: — | H12: Cannot reach the site to read the terms. | I12: LOW — only 17 sections held. | J12: Write to the Department of Justice NI, which absorbed the Commission's functions, for the re-use position and an archive copy. | K12: DoJ NI — via justice-ni.gov.uk | L12: Low priority
... A21: LIC20 | B21: All gov.uk, legislation.gov.uk and parliamentary sources | C21: primary-acts-*, si-*, regional, retained-eu, hmrc-*, pwdata-*, committees-*, historic-hansard and others | D21: ogl-3.0 / opl-3.0 / eu-2011-833 | E21: CLEAR | F21: Yes | G21: 12 Jun 2026 | H21: Open Government Licence v3.0 and the Open Parliament Licence permit copying, publishing, adapting and commercial exploitation with attribution. | I21: NONE. This covers the large majority of the corpus by volume. | J21: None. Keep attribution carried per section. | K21: — | L21: Done
B23: THREE LETTERS TO WRITE FIRST — in this order
B24: 1. The National Archives (Find Case Law) — we are indexing 74,896 judgments under a licence that excludes computational analysis. This is the only one where we are outside the terms on content we already hold and serve.
B25: 2. The FCA — same problem, smaller volume (3,661 sections), but it also gates a 146,000-section backfill of the most commercially valuable corpus available to us.
B26: 3. BAILII — not a breach, but a courtesy that gates the single largest gap in the corpus. A charity that gets a polite letter first is an ally; one that finds a crawler is not.

Sheet Quangos
A1: Organisation | B1: GOV.UK slug | C1: Body type | D1: GOV.UK status | E1: Parent department | F1: Total docs on GOV.UK | G1: Relevant docs | H1: Guidance | I1: Statutory guidance | J1: Detailed guide | K1: Manual sections | L1: Manuals | M1: Policy papers | N1: Decisions | O1: Regulations | P1: Notices | Q1: Research | R1: Independent reports | S1: Impact assessments | T1: Corporate reports | U1: Consultation outcomes | V1: Government responses | W1: Other relevant | X1: Publishes on own site? | Y1: Ingest wave
A2: Air Accidents Investigation Branch | B2: air-accidents-investigation-branch | C2: Other | D2: live | E2: department-for-transport | F2: 12287 | G2: 11732 | H2: 21 | I2: 0 | J2: 1 | K2: 0 | L2: 0 | M2: 9 | N2: 0 | O2: 16 | P2: 0 | Q2: 0 | R2: 342 | S2: 0 | T2: 1 | U2: 0 | V2: 0 | W2: 11342 | X2: No | Y2: Wave 1 — GOV.UK Content API
A3: HM Revenue & Customs | B3: hm-revenue-customs | C3: Non-ministerial department | D3: live | F3: 100281 | G3: 8487 | H3: 1611 | I3: 76 | J3: 2047 | K3: 924 | L3: 66 | M3: 1905 | N3: 10 | O3: 0 | P3: 73 | Q3: 766 | R3: 4 | S3: 100 | T3: 454 | U3: 336 | V3: 23 | W3: 92 | X3: No | Y3: Wave 1 — GOV.UK Content API
A4: Environment Agency | B4: environment-agency | C4: Executive non-departmental public body | D4: live | E4: department-for-environment-food-rural-affairs | F4: 11443 | G4: 7639 | H4: 483 | I4: 186 | J4: 465 | K4: 184 | L4: 19 | M4: 421 | N4: 330 | O4: 0 | P4: 3981 | Q4: 1008 | R4: 3 | S4: 2 | T4: 134 | U4: 132 | V4: 11 | W4: 280 | X4: No | Y4: Wave 1 — GOV.UK Content API
A5: Department for Environment, Food & Rural Affairs | B5: department-for-environment-food-rural-affairs | C5: Ministerial department | D5: live | F5: 21049 | G5: 4630 | H5: 752 | I5: 132 | J5: 799 | K5: 9 | L5: 1 | M5: 1006 | N5: 181 | O5: 0 | P5: 21 | Q5: 528 | R5: 132 | S5: 15 | T5: 200 | U5: 504 | V5: 74 | W5: 276 | X5: No | Y5: Wave 1 — GOV.UK Content API
A6: Department for Education | B6: department-for-education | C6: Ministerial department | D6: live | F6: 11075 | G6: 4038 | H6: 1048 | I6: 82 | J6: 281 | K6: 165 | L6: 15 | M6: 322 | N6: 174 | O6: 0 | P6: 2 | Q6: 1233 | R6: 133 | S6: 93 | T6: 114 | U6: 301 | V6: 37 | W6: 38 | X6: No | Y6: Wave 1 — GOV.UK Content API
A7: Home Office | B7: home-office | C7: Ministerial department | D7: live | F7: 13921 | G7: 3943 | H7: 1277 | I7: 47 | J7: 123 | K7: 101 | L7: 1 | M7: 1162 | N7: 2 | O7: 0 | P7: 17 | Q7: 357 | R7: 194 | S7: 68 | T7: 305 | U7: 246 | V7: 11 | W7: 32 | X7: No | Y7: Wave 1 — GOV.UK Content API
A8: Department of Health and Social Care | B8: department-of-health-and-social-care | C8: Ministerial department | D8: live | F8: 10641 | G8: 3753 | H8: 1205 | I8: 69 | J8: 85 | K8: 34 | L8: 1 | M8: 1062 | N8: 5 | O8: 1 | P8: 9 | Q8: 210 | R8: 400 | S8: 101 | T8: 182 | U8: 280 | V8: 54 | W8: 55 | X8: No | Y8: Wave 1 — GOV.UK Content API
A9: Ministry of Defence | B9: ministry-of-defence | C9: Ministerial department | D9: live | F9: 14840 | G9: 3611 | H9: 1032 | I9: 3 | J9: 244 | K9: 0 | L9: 0 | M9: 288 | N9: 0 | O9: 608 | P9: 29 | Q9: 160 | R9: 82 | S9: 10 | T9: 538 | U9: 85 | V9: 7 | W9: 525 | X9: No | Y9: Wave 1 — GOV.UK Content API
A10: HM Treasury | B10: hm-treasury | C10: Ministerial department | D10: live | F10: 9657 | G10: 3359 | H10: 603 | I10: 19 | J10: 26 | K10: 0 | L10: 0 | M10: 1291 | N10: 0 | O10: 0 | P10: 15 | Q10: 146 | R10: 59 | S10: 9 | T10: 755 | U10: 359 | V10: 4 | W10: 73 | X10: No | Y10: Wave 1 — GOV.UK Content API
A11: Foreign, Commonwealth & Development Office | B11: foreign-commonwealth-development-office | C11: Ministerial department | D11: live | F11: 48187 | G11: 3189 | H11: 1505 | I11: 39 | J11: 508 | K11: 0 | L11: 0 | M11: 769 | N11: 9 | O11: 0 | P11: 8 | Q11: 91 | R11: 9 | S11: 10 | T11: 167 | U11: 0 | V11: 71 | W11: 3 | X11: No | Y11: Wave 1 — GOV.UK Content API
A12: Department for Transport | B12: department-for-transport | C12: Ministerial department | D12: live | F12: 10528 | G12: 3078 | H12: 709 | I12: 52 | J12: 109 | K12: 62 | L12: 2 | M12: 368 | N12: 142 | O12: 0 | P12: 41 | Q12: 678 | R12: 114 | S12: 19 | T12: 274 | U12: 446 | V12: 21 | W12: 41 | X12: No | Y12: Wave 1 — GOV.UK Content API
A13: Department for Work and Pensions | B13: department-for-work-pensions | C13: Ministerial department | D13: live | F13: 10821 | G13: 2847 | H13: 518 | I13: 13 | J13: 115 | K13: 28 | L13: 1 | M13: 318 | N13: 2 | O13: 0 | P13: 1 | Q13: 887 | R13: 180 | S13: 181 | T13: 320 | U13: 246 | V13: 14 | W13: 23 | X13: No | Y13: Wave 1 — GOV.UK Content API
A14: Department for Energy Security and Net Zero | B14: department-for-energy-security-and-net-zero | C14: Ministerial department | D14: live | F14: 4839 | G14: 2766 | H14: 392 | I14: 13 | J14: 96 | K14: 9 | L14: 1 | M14: 243 | N14: 683 | O14: 0 | P14: 407 | Q14: 645 | R14: 34 | S14: 10 | T14: 56 | U14: 128 | V14: 1 | W14: 48 | X14: No | Y14: Wave 1 — GOV.UK Content API
A15: Cabinet Office | B15: cabinet-office | C15: Ministerial department | D15: live | F15: 7668 | G15: 2758 | H15: 845 | I15: 6 | J15: 109 | K15: 0 | L15: 0 | M15: 1012 | N15: 57 | O15: 0 | P15: 27 | Q15: 135 | R15: 80 | S15: 13 | T15: 357 | U15: 77 | V15: 20 | W15: 20 | X15: No | Y15: Wave 1 — GOV.UK Content API
A16: HM Courts & Tribunals Service | B16: hm-courts-and-tribunals-service | C16: Executive agency | D16: live | E16: ministry-of-justice | F16: 156942 | G16: 2534 | H16: 181 | I16: 1 | J16: 126 | K16: 0 | L16: 0 | M16: 7 | N16: 1 | O16: 0 | P16: 1 | Q16: 19 | R16: 2 | S16: 0 | T16: 52 | U16: 12 | V16: 12 | W16: 2120 | X16: No | Y16: Wave 1 — GOV.UK Content API
A17: Ministry of Justice | B17: ministry-of-justice | C17: Ministerial department | D17: live | F17: 8026 | G17: 2509 | H17: 470 | I17: 9 | J17: 480 | K17: 12 | L17: 2 | M17: 582 | N17: 1 | O17: 0 | P17: 9 | Q17: 343 | R17: 65 | S17: 15 | T17: 300 | U17: 175 | V17: 8 | W17: 38 | X17: No | Y17: Wave 1 — GOV.UK Content API
A18: Ministry of Housing, Communities & Local Government (2018 to 2021) | B18: ministry-of-housing-communities-and-local-government-2018-2021 | C18: Ministerial department | D18: closed | F18: 10849 | G18: 2504 | H18: 698 | I18: 35 | J18: 120 | K18: 0 | L18: 0 | M18: 635 | N18: 5 | O18: 0 | P18: 2 | Q18: 228 | R18: 91 | S18: 106 | T18: 94 | U18: 372 | V18: 88 | W18: 30 | X18: No | Y18: Wave 3 — archive only
A19: Public Health England | B19: public-health-england | C19: Executive agency | D19: closed | E19: department-of-health-and-social-care | F19: 5598 | G19: 2457 | H19: 996 | I19: 0 | J19: 159 | K19: 0 | L19: 0 | M19: 50 | N19: 0 | O19: 0 | P19: 0 | Q19: 1018 | R19: 53 | S19: 5 | T19: 131 | U19: 33 | V19: 0 | W19: 12 | X19: No | Y19: Wave 3 — archive only
A20: Department for Business, Energy & Industrial Strategy | B20: department-for-business-energy-and-industrial-strategy | C20: Ministerial department | D20: closed | F20: 7019 | G20: 2399 | H20: 379 | I20: 8 | J20: 129 | K20: 0 | L20: 0 | M20: 259 | N20: 171 | O20: 1 | P20: 233 | Q20: 609 | R20: 65 | S20: 11 | T20: 177 | U20: 320 | V20: 16 | W20: 21 | X20: No | Y20: Wave 3 — archive only
A21: Company Names Tribunal | B21: company-names-tribunal | C21: Other | D21: live | E21: intellectual-property-office | F21: 2315 | G21: 2302 | H21: 6 | I21: 0 | J21: 1 | K21: 0 | L21: 0 | M21: 0 | N21: 2287 | O21: 0 | P21: 8 | Q21: 0 | R21: 0 | S21: 0 | T21: 0 | U21: 0 | V21: 0 | W21: 0 | X21: No | Y21: Wave 1 — GOV.UK Content API
A22: Office of the Schools Adjudicator | B22: office-of-the-schools-adjudicator | C22: Other | D22: live | E22: department-for-education | F22: 2230 | G22: 2217 | H22: 0 | I22: 0 | J22: 3 | K22: 0 | L22: 0 | M22: 0 | N22: 2213 | O22: 0 | P22: 0 | Q22: 0 | R22: 0 | S22: 0 | T22: 1 | U22: 0 | V22: 0 | W22: 0 | X22: No | Y22: Wave 1 — GOV.UK Content API
A23: Foreign & Commonwealth Office | B23: foreign-commonwealth-office | C23: Ministerial department | D23: closed | F23: 16523 | G23: 2204 | H23: 816 | I23: 0 | J23: 68 | K23: 0 | L23: 0 | M23: 406 | N23: 0 | O23: 0 | P23: 8 | Q23: 442 | R23: 20 | S23: 5 | T23: 390 | U23: 20 | V23: 27 | W23: 2 | X23: No | Y23: Wave 3 — archive only
A24: Department for International Development | B24: department-for-international-development | C24: Ministerial department | D24: closed | F24: 5621 | G24: 2073 | H24: 167 | I24: 0 | J24: 46 | K24: 0 | L24: 0 | M24: 737 | N24: 0 | O24: 0 | P24: 2 | Q24: 93 | R24: 596 | S24: 19 | T24: 373 | U24: 6 | V24: 33 | W24: 1 | X24: No | Y24: Wave 3 — archive only
A25: Department for Digital, Culture, Media & Sport | B25: department-for-digital-culture-media-sport | C25: Ministerial department | D25: closed | F25: 7420 | G25: 2068 | H25: 301 | I25: 7 | J25: 139 | K25: 0 | L25: 0 | M25: 411 | N25: 9 | O25: 4 | P25: 36 | Q25: 290 | R25: 93 | S25: 30 | T25: 517 | U25: 181 | V25: 12 | W25: 38 | X25: No | Y25: Wave 3 — archive only
A26: Department for Business and Trade | B26: department-for-business-and-trade | C26: Ministerial department | D26: live | F26: 4133 | G26: 2031 | H26: 588 | I26: 29 | J26: 301 | K26: 16 | L26: 2 | M26: 335 | N26: 40 | O26: 0 | P26: 219 | Q26: 281 | R26: 49 | S26: 16 | T26: 53 | U26: 53 | V26: 5 | W26: 44 | X26: No | Y26: Wave 1 — GOV.UK Content API
A27: Upper Tribunal (Administrative Appeals Chamber) | B27: upper-tribunal-administrative-appeals-chamber | C27: Tribunal | D27: live | E27: hm-courts-and-tribunals-service | F27: 2022 | G27: 2019 | H27: 0 | I27: 0 | J27: 0 | K27: 0 | L27: 0 | M27: 0 | N27: 0 | O27: 0 | P27: 0 | Q27: 0 | R27: 0 | S27: 0 | T27: 0 | U27: 0 | V27: 0 | W27: 2019 | X27: No | Y27: Wave 1 — GOV.UK Content API
A28: Ministry of Housing, Communities and Local Government | B28: ministry-of-housing-communities-local-government | C28: Ministerial department | D28: live | F28: 3254 | G28: 1753 | H28: 709 | I28: 50 | J28: 411 | K28: 110 | L28: 10 | M28: 120 | N28: 10 | O28: 0 | P28: 2 | Q28: 162 | R28: 49 | S28: 4 | T28: 12 | U28: 55 | V28: 0 | W28: 49 | X28: No | Y28: Wave 1 — GOV.UK Content API
A29: Intellectual Property Office | B29: intellectual-property-office | C29: Executive agency | D29: live | E29: department-for-science-innovation-and-technology | F29: 2754 | G29: 1742 | H29: 158 | I29: 78 | J29: 130 | K29: 434 | L29: 7 | M29: 9 | N29: 441 | O29: 0 | P29: 135 | Q29: 145 | R29: 0 | S29: 1 | T29: 23 | U29: 44 | V29: 0 | W29: 137 | X29: No | Y29: Wave 1 — GOV.UK Content API
A30: Department for Business, Innovation & Skills | B30: department-for-business-innovation-skills | C30: Ministerial department | D30: closed | F30: 6029 | G30: 1666 | H30: 19 | I30: 0 | J30: 4 | K30: 0 | L30: 0 | M30: 415 | N30: 2 | O30: 0 | P30: 8 | Q30: 719 | R30: 57 | S30: 92 | T30: 135 | U30: 188 | V30: 8 | W30: 19 | X30: No | Y30: Wave 3 — archive only
A31: Teaching Regulation Agency | B31: teaching-regulation-agency | C31: Executive agency | D31: live | E31: department-for-education | F31: 1672 | G31: 1663 | H31: 8 | I31: 0 | J31: 6 | K31: 0 | L31: 0 | M31: 0 | N31: 1639 | O31: 0 | P31: 0 | Q31: 0 | R31: 0 | S31: 0 | T31: 10 | U31: 0 | V31: 0 | W31: 0 | X31: No | Y31: Wave 1 — GOV.UK Content API
A32: Certification Officer | B32: certification-officer | C32: Other | D32: live | E32: department-for-business-and-trade | F32: 1795 | G32: 1587 | H32: 6 | I32: 0 | J32: 11 | K32: 0 | L32: 0 | M32: 0 | N32: 525 | O32: 0 | P32: 0 | Q32: 0 | R32: 0 | S32: 0 | T32: 1045 | U32: 0 | V32: 0 | W32: 0 | X32: No | Y32: Wave 1 — GOV.UK Content API
A33: UK Health Security Agency | B33: uk-health-security-agency | C33: Executive agency | D33: live | E33: department-of-health-and-social-care | F33: 3564 | G33: 1573 | H33: 698 | I33: 0 | J33: 375 | K33: 0 | L33: 0 | M33: 5 | N33: 0 | O33: 0 | P33: 0 | Q33: 426 | R33: 9 | S33: 1 | T33: 54 | U33: 2 | V33: 0 | W33: 3 | X33: No | Y33: Wave 1 — GOV.UK Content API
A34: Department of Energy & Climate Change | B34: department-of-energy-climate-change | C34: Ministerial department | D34: closed | F34: 5098 | G34: 1466 | H34: 142 | I34: 2 | J34: 2 | K34: 0 | L34: 0 | M34: 398 | N34: 2 | O34: 3 | P34: 1 | Q34: 323 | R34: 50 | S34: 49 | T34: 213 | U34: 234 | V34: 24 | W34: 23 | X34: No | Y34: Wave 3 — archive only
A35: UK Visas and Immigration | B35: uk-visas-and-immigration | C35: Sub organisation | D35: live | E35: home-office | F35: 2574 | G35: 1416 | H35: 955 | I35: 4 | J35: 50 | K35: 0 | L35: 0 | M35: 321 | N35: 0 | O35: 0 | P35: 1 | Q35: 32 | R35: 6 | S35: 20 | T35: 12 | U35: 10 | V35: 0 | W35: 5 | X35: No | Y35: Wave 1 — GOV.UK Content API
A36: High Speed Two (HS2) Limited | B36: high-speed-two-limited | C36: Executive non-departmental public body | D36: live | E36: department-for-transport | F36: 2437 | G36: 1380 | H36: 141 | I36: 3 | J36: 2 | K36: 0 | L36: 0 | M36: 211 | N36: 2 | O36: 0 | P36: 3 | Q36: 64 | R36: 81 | S36: 759 | T36: 68 | U36: 46 | V36: 0 | W36: 0 | X36: No | Y36: Wave 1 — GOV.UK Content API
A37: Department for Levelling Up, Housing and Communities | B37: department-for-levelling-up-housing-and-communities | C37: Other | D37: closed | F37: 3321 | G37: 1324 | H37: 408 | I37: 29 | J37: 363 | K37: 0 | L37: 0 | M37: 208 | N37: 4 | O37: 0 | P37: 1 | Q37: 128 | R37: 65 | S37: 6 | T37: 11 | U37: 80 | V37: 0 | W37: 21 | X37: No | Y37: Wave 3 — archive only
A38: Marine Accident Investigation Branch | B38: marine-accident-investigation-branch | C38: Other | D38: live | E38: department-for-transport | F38: 1695 | G38: 1320 | H38: 12 | I38: 0 | J38: 0 | K38: 0 | L38: 0 | M38: 8 | N38: 0 | O38: 0 | P38: 0 | Q38: 175 | R38: 0 | S38: 0 | T38: 26 | U38: 3 | V38: 0 | W38: 1096 | X38: No | Y38: Wave 1 — GOV.UK Content API
A39: Department for Culture, Media and Sport | B39: department-for-culture-media-and-sport | C39: Ministerial department | D39: live | F39: 2477 | G39: 1316 | H39: 229 | I39: 9 | J39: 155 | K39: 0 | L39: 0 | M39: 317 | N39: 0 | O39: 1 | P39: 37 | Q39: 352 | R39: 76 | S39: 23 | T39: 76 | U39: 27 | V39: 0 | W39: 14 | X39: No | Y39: Wave 1 — GOV.UK Content API
A40: Department for Science, Innovation and Technology | B40: department-for-science-innovation-and-technology | C40: Ministerial department | D40: live | F40: 2718 | G40: 1306 | H40: 217 | I40: 5 | J40: 144 | K40: 5 | L40: 1 | M40: 300 | N40: 0 | O40: 3 | P40: 119 | Q40: 349 | R40: 78 | S40: 12 | T40: 42 | U40: 13 | V40: 4 | W40: 14 | X40: No | Y40: Wave 1 — GOV.UK Content API
...

Sheet Issues Log
A1: ID | B1: Severity | C1: Affects | D1: What a user would see | E1: What is actually wrong | F1: How we fix it | G1: Decision status
A2: I01 | B2: CRITICAL | C2: Daily ingest email, all collections | D2: The email says '100% complete' next to 62 of 77 collections, so the corpus looks finished. | E2: For 46 of them the target was set by copying the number of sections we ended up with. The email prints compiled ÷ compiled, which is 100% for any corpus including an empty one. There is no upper clamp either, so explanatory-notes prints '100% complete' at 4,549% of its target. | F2: Rewrite the reporter to read a new corpus_census table, never corpus_targets.est_sections. Four states, and a percentage only where a publisher walk exists. | G2: Briefed to CC
A3: I02 | B3: CRITICAL | C3: tna-caselaw — licence | D3: Nothing visible. This is a legal exposure, not a bug. | E3: The Open Justice Licence v2.0 excludes computational analysis, which it defines to include search indexing and bulk processing. We hold 74,896 judgments, have embedded them and serve them through full-text search. | F3: Charlie writes to The National Archives for the separate computational-analysis licence. See the Licences tab, LIC01. | G3: CHARLIE — do first
A4: I03 | B4: CRITICAL | C4: fca-handbook — licence | D4: Nothing visible. | E4: FCA terms require prior written permission to reproduce or store the Handbook in any retrieval system. We are storing 3,661 sections now, and the plan is to grow that to ~150,000. | F4: Charlie writes to the FCA before any backfill. See LIC03. | G4: CHARLIE — do first
A5: I04 | B5: HIGH | C5: Case law before 2001 | D5: Ask about any leading case decided before 2001 and the platform returns nothing, or returns a modern case that cites it. It looks like the law does not exist. | E5: All four BAILII targets were retired as 'superseded by tna-caselaw'. tna-caselaw starts in 2001, so nothing superseded them. This is the largest known gap in the corpus. | F5: Walk BAILII per court per decade to size it, then fetch. Charlie writes to BAILII first. | G5: AUTHORISED 23 Aug
A6: I05 | B6: HIGH | C6: et-decisions | D6: Search an employment-law question and get back a near-empty stub page instead of the decision. | E6: 131,654 of 293,403 rows (44.9%) are a landing page, not a decision — median 18 words. They are counted as content and compete with real decisions for rank. | F6: Delete the 131,654 rows and vectors, then re-fetch the real decisions. | G6: AUTHORISED 23 Aug — delete and re-fetch
A7: I06 | B7: HIGH | C7: Three retired collections | D7: The same written question comes back twice in one result set. | E7: lda-lordswrittenquestions (20,500), lda-commonswrittenquestions (8,000) and written-statements (129) were retired, but only the target row was removed. The 28,629 sections and their vectors are still there and still served. | F7: Delete the rows AND the vectors. Prove it with a query that used to return one. | G7: AUTHORISED 23 Aug
A8: I07 | B8: HIGH | C8: tna-caselaw — content quality | D8: A case-law result whose summary is a fragment of CSS rather than the judgment. | E8: 12.7% of all embedded case-law text is stylesheet markup, and chunk 0 — the chunk most likely to be retrieved — is more than half markup in 77% of judgments. | F8: Strip the stylesheet and re-embed chunk 0. About $31 on the Gemini batch endpoint. | G8: AUTHORISED 23 Aug
A9: I08 | B9: HIGH | C9: building-regs | D9: Ask about fire safety or means of escape and get almost nothing, when Approved Document B is one of the most-read documents in the country. | E9: 21 rows at roughly 446 words each. Approved Documents run to tens of thousands of words. The PDF text is not being captured — we have the covers, not the contents. | F9: Fix PDF extraction, then re-fetch. Note that these documents incorporate BSI standards by reference, which we cannot hold — say so rather than answer as if complete. | G9: Needs a sprint
A10: I09 | B10: HIGH | C10: senedd-cofnod | D10: A Senedd result attributed to the wrong debate, or a Welsh-language passage returned to an English-language query where it cannot be read. | E10: 61.1% of 191,730 speeches carry an inherited heading from the wrong parent. Roughly 95% of a 40-row sample had Welsh-language bodies. | F10: Fix heading inheritance in the SHARED parser, not per caller. The Welsh-language question is a product decision, not an ingest one. | G10: CHARLIE DECISION on Welsh
A11: I10 | B11: HIGH | C11: written-answers | D11: A single search result containing an entire year of written answers. | E11: 143 rows at roughly 306,000 words each — whole source files stored as one section. | F11: Re-split into one section per answer. | G11: Needs a sprint
A12: I11 | B12: MEDIUM | C12: govuk-core-docs | D12: Ask for the Ministerial Code or a PACE code and get a fragment, or nothing. | E12: One 175-section collection is standing in for four separate plan rows — PACE codes, civil service and ministerial codes, Treasury Green and Magenta Books, and White Papers — estimated at 1,800+ sections combined. Nothing in it can be reported on separately. | F12: Split into four collections, then walk each. Charlie asked specifically for police and civil service codes; they are technically held but indistinguishably mixed and almost certainly incomplete. | G12: Needs a sprint
... A19: I18 | B19: LOW | C19: lgsco | D19: Ask about a council complaint and get almost nothing. | E19: 40 sections held against an internal estimate of about 100. The real published figure is likely tens of thousands. One fetch failure outstanding. | F19: Walk for a real denominator; retry the failure. | G19: Briefed to CC

Sheet Original Plan v3
A1: Corpus / Source | B1: Category | C1: Sub-category | D1: Access | E1: IP Owner | F1: Ingest Method | G1: Est. Documents | H1: Est. Sections | I1: Compilation Model | J1: Worker Phase 1 | K1: Worker Phase 2 | L1: Priority | M1: Status | N1: Notes | O1: Live corpus key(s) | P1: Sections ingested | Q1: % of Est. Sections (H) ingested | R1: Sections embedded | S1: % of Est. Sections (H) embedded | T1: % of ingested that is embedded | U1: Source-confirmed instrument coverage | V1: Coverage note (measured 2026-08-22)
A2: PRIMARY LEGISLATION
A3: UK Primary Acts (~4,500) | B3: Statute | C3: Primary | D3: Open | E3: Crown / OGL | F3: TNA CLML API | G3: 4,500 | H3: 180,000 | I3: Gemini 2.5 Flash | J3: Workers 1+2 | K3: → Hansard | L3: 1 | M3: Pending | N3: UKPGA back to 1267 (Statute of Marlborough). Split pre/post-2000 across 2 workers. | O3: primary-acts-pre-2000, primary-acts-2000plus | P3: 314078 | Q3: 174.5 | R3: 314072 | S3: 174.5 | T3: 100 | U3: ukpga 4,493 of 17,560 = 25.6% (43.7% excl. no-provisions) | V3: Source-walked: 4,493 of 17,560 published ukpga instruments present (25.6%); 99.5% for 2000+, 21.4% pre-2000.
A4: Statutory Instruments (~60,000) | B4: Statute | C4: Secondary | D4: Open | E4: Crown / OGL | F4: TNA CLML API | G4: 60,000 | H4: 600,000 | I4: Gemini 2.5 Flash | J4: Workers 3+4 | K4: → Hansard | L4: 1 | M4: Pending | N4: 3× section volume of Acts. Split pre/post-2010 across 2 workers. | O4: si-pre-2010, si-2010plus | P4: 738553 | Q4: 123.1 | R4: 738526 | S4: 123.1 | T4: 100 | U4: uksi 73,558 of 109,190 = 67.4% (72.9% excl. no-provisions) | V4: Source-walked: 73,558 of 109,190 published uksi instruments (67.4%).
A5: Retained EU Law (~4,000) | B5: Statute | C5: Secondary | D5: Open | E5: Crown / OGL | F5: TNA CLML API | G5: 4,000 | H5: 80,000 | I5: Gemini 2.5 Flash | J5: Worker 6 | K5: → BAILII phase 2 | L5: 2 | M5: Pending | N5: EU-origin instruments now on legislation.gov.uk post-Brexit. | O5: retained-eu | P5: 199224 | Q5: 249 | R5: 199224 | S5: 249 | T5: 100 | U5: eur/eudn/eudr 39,068 of 159,773 = 24.5% (84.7% excl. no-provisions) | V5: Source-walked: 39,068 of 159,773 (24.5%); 113,623 of the absences are declared no-provisions at source.
A6: Scottish Acts + SSIs | B6: Statute | C6: Devolved Primary+Secondary | D6: Open | E6: Crown / OGL | F6: TNA CLML API | H6: 90,000 | I6: Gemini 2.5 Flash | J6: Worker 5 | K6: → BAILII phase 1 | L6: 2 | M6: Pending | N6: Scottish Parliament legislation via legislation.gov.uk. | O6: regional | P6: 341093 | Q6: 379 | R6: 341083 | S6: 379 | T6: 100 | U6: asp+ssi 8,900 of 11,804 = 75.4% (90.3% excl. no-provisions) | V6: Rows 6-8 all land in the single `regional` collection; it cannot be split by nation without re-deriving from the id prefix.
A7: Welsh Acts + SIs | B7: Statute | C7: Devolved Primary+Secondary | D7: Open | E7: Crown / OGL | F7: TNA CLML API | H7: 40,000 | I7: Gemini 2.5 Flash | J7: Worker 5 | K7: → BAILII phase 1 | L7: 2 | M7: Pending | N7: Senedd legislation. | O7: regional | P7: 341093 | Q7: 852.7 | R7: 341083 | S7: 852.7 | T7: 100 | U7: wsi+anaw+asc 4,772 of 6,841 = 69.8% (97.4% excl. no-provisions) | V7: See row 6 - shared collection, not separately counted.
A8: NI Acts + Orders | B8: Statute | C8: Devolved Primary+Secondary | D8: Open | E8: Crown / OGL | F8: TNA CLML API | H8: 30,000 | I8: Gemini 2.5 Flash | J8: Worker 5 | K8: → BAILII phase 1 | L8: 2 | M8: Pending | N8: Northern Ireland Assembly + Westminster Orders in Council. | O8: regional | P8: 341093 | Q8: 1137 | R8: 341083 | S8: 1136.9 | T8: 100 | U8: nisr+nia+nisi 12,478 of 19,454 = 64.1% (95.8% excl. no-provisions) | V8: See row 6 - shared collection, not separately counted.
A9: Local / Private Acts | B9: Statute | C9: Primary | D9: Open | E9: Crown / OGL | F9: TNA CLML API | H9: 10,000 | I9: Gemini 2.5 Flash | J9: Worker 8 | K9: → Law Commission | L9: 4 | M9: Pending | N9: Lower priority – limited policy relevance. | O9: — | P9: 0 | Q9: 0 | R9: 0 | S9: 0 | T9: — | U9: — | V9: NOT INGESTED. No `ukla` seeder exists and no corpus_targets row was ever created.
A10: TAX & FINANCIAL REGULATION
